/home/db_user/datacup-challenge-esi-dev/RequeteAPI/venv/bin/python: can't open file '/home/db_user/datacup-challenge-esi-dev/RequeteAPI/Importregulier.py': [Errno 2] No such file or directory
/home/db_user/datacup-challenge-esi-dev/RequeteAPI/venv/bin/python: can't open file '/home/db_user/datacup-challenge-esi-dev/RequeteAPI/Importregulier.py': [Errno 2] No such file or directory
/home/db_user/datacup-challenge-esi-dev/RequeteAPI/venv/bin/python: can't open file '/home/db_user/datacup-challenge-esi-dev/RequeteAPI/Importregulier.py': [Errno 2] No such file or directory
/home/db_user/datacup-challenge-esi-dev/RequeteAPI/venv/bin/python: can't open file '/home/db_user/datacup-challenge-esi-dev/RequeteAPI/Importregulier.py': [Errno 2] No such file or directory
/home/db_user/datacup-challenge-esi-dev/RequeteAPI/venv/bin/python: can't open file '/home/db_user/datacup-challenge-esi-dev/RequeteAPI/Importregulier.py': [Errno 2] No such file or directory
/home/db_user/datacup-challenge-esi-dev/RequeteAPI/venv/bin/python: can't open file '/home/db_user/datacup-challenge-esi-dev/RequeteAPI/Importregulier.py': [Errno 2] No such file or directory
/home/db_user/datacup-challenge-esi-dev/RequeteAPI/venv/bin/python: can't open file '/home/db_user/datacup-challenge-esi-dev/RequeteAPI/Importregulier.py': [Errno 2] No such file or directory
/home/db_user/datacup-challenge-esi-dev/RequeteAPI/venv/bin/python: can't open file '/home/db_user/datacup-challenge-esi-dev/RequeteAPI/Importregulier.py': [Errno 2] No such file or directory
/home/db_user/datacup-challenge-esi-dev/RequeteAPI/venv/bin/python: can't open file '/home/db_user/datacup-challenge-esi-dev/RequeteAPI/Importregulier.py': [Errno 2] No such file or directory
/home/db_user/datacup-challenge-esi-dev/RequeteAPI/venv/bin/python: can't open file '/home/db_user/datacup-challenge-esi-dev/RequeteAPI/Importregulier.py': [Errno 2] No such file or directory
/home/db_user/datacup-challenge-esi-dev/RequeteAPI/venv/bin/python: can't open file '/home/db_user/datacup-challenge-esi-dev/RequeteAPI/Importregulier.py': [Errno 2] No such file or directory
/home/db_user/datacup-challenge-esi-dev/RequeteAPI/venv/bin/python: can't open file '/home/db_user/datacup-challenge-esi-dev/RequeteAPI/Importregulier.py': [Errno 2] No such file or directory
/home/db_user/datacup-challenge-esi-dev/RequeteAPI/venv/bin/python: can't open file '/home/db_user/datacup-challenge-esi-dev/RequeteAPI/Importregulier.py': [Errno 2] No such file or directory
/home/db_user/datacup-challenge-esi-dev/RequeteAPI/venv/bin/python: can't open file '/home/db_user/datacup-challenge-esi-dev/RequeteAPI/Importregulier.py': [Errno 2] No such file or directory
/home/db_user/datacup-challenge-esi-dev/RequeteAPI/venv/bin/python: can't open file '/home/db_user/datacup-challenge-esi-dev/RequeteAPI/Importregulier.py': [Errno 2] No such file or directory
/home/db_user/datacup-challenge-esi-dev/RequeteAPI/venv/bin/python: can't open file '/home/db_user/datacup-challenge-esi-dev/RequeteAPI/Importregulier.py': [Errno 2] No such file or directory
/home/db_user/datacup-challenge-esi-dev/RequeteAPI/venv/bin/python: can't open file '/home/db_user/datacup-challenge-esi-dev/RequeteAPI/Importregulier.py': [Errno 2] No such file or directory
/home/db_user/datacup-challenge-esi-dev/RequeteAPI/venv/bin/python: can't open file '/home/db_user/datacup-challenge-esi-dev/RequeteAPI/Importregulier.py': [Errno 2] No such file or directory
/home/db_user/datacup-challenge-esi-dev/RequeteAPI/venv/bin/python: can't open file '/home/db_user/datacup-challenge-esi-dev/RequeteAPI/Importregulier.py': [Errno 2] No such file or directory
/home/db_user/datacup-challenge-esi-dev/RequeteAPI/venv/bin/python: can't open file '/home/db_user/datacup-challenge-esi-dev/RequeteAPI/Importregulier.py': [Errno 2] No such file or directory
/home/db_user/datacup-challenge-esi-dev/RequeteAPI/venv/bin/python: can't open file '/home/db_user/datacup-challenge-esi-dev/RequeteAPI/Importregulier.py': [Errno 2] No such file or directory
/home/db_user/datacup-challenge-esi-dev/RequeteAPI/venv/bin/python: can't open file '/home/db_user/datacup-challenge-esi-dev/RequeteAPI/Importregulier.py': [Errno 2] No such file or directory
/home/db_user/datacup-challenge-esi-dev/RequeteAPI/venv/bin/python: can't open file '/home/db_user/datacup-challenge-esi-dev/RequeteAPI/Importregulier.py': [Errno 2] No such file or directory
/home/db_user/datacup-challenge-esi-dev/RequeteAPI/venv/bin/python: can't open file '/home/db_user/datacup-challenge-esi-dev/RequeteAPI/Importregulier.py': [Errno 2] No such file or directory
/home/db_user/datacup-challenge-esi-dev/RequeteAPI/venv/bin/python: can't open file '/home/db_user/datacup-challenge-esi-dev/RequeteAPI/Importregulier.py': [Errno 2] No such file or directory
/home/db_user/datacup-challenge-esi-dev/RequeteAPI/venv/bin/python: can't open file '/home/db_user/datacup-challenge-esi-dev/RequeteAPI/Importregulier.py': [Errno 2] No such file or directory
/home/db_user/datacup-challenge-esi-dev/RequeteAPI/venv/bin/python: can't open file '/home/db_user/datacup-challenge-esi-dev/RequeteAPI/Importregulier.py': [Errno 2] No such file or directory
/home/db_user/datacup-challenge-esi-dev/RequeteAPI/venv/bin/python: can't open file '/home/db_user/datacup-challenge-esi-dev/RequeteAPI/Importregulier.py': [Errno 2] No such file or directory
/home/db_user/datacup-challenge-esi-dev/RequeteAPI/venv/bin/python: can't open file '/home/db_user/datacup-challenge-esi-dev/RequeteAPI/Importregulier.py': [Errno 2] No such file or directory
/home/db_user/datacup-challenge-esi-dev/RequeteAPI/venv/bin/python: can't open file '/home/db_user/datacup-challenge-esi-dev/RequeteAPI/Importregulier.py': [Errno 2] No such file or directory
/home/db_user/datacup-challenge-esi-dev/RequeteAPI/venv/bin/python: can't open file '/home/db_user/datacup-challenge-esi-dev/RequeteAPI/Importregulier.py': [Errno 2] No such file or directory
/home/db_user/datacup-challenge-esi-dev/RequeteAPI/venv/bin/python: can't open file '/home/db_user/datacup-challenge-esi-dev/RequeteAPI/Importregulier.py': [Errno 2] No such file or directory
/home/db_user/datacup-challenge-esi-dev/RequeteAPI/venv/bin/python: can't open file '/home/db_user/datacup-challenge-esi-dev/RequeteAPI/Importregulier.py': [Errno 2] No such file or directory
/home/db_user/datacup-challenge-esi-dev/RequeteAPI/venv/bin/python: can't open file '/home/db_user/datacup-challenge-esi-dev/RequeteAPI/Importregulier.py': [Errno 2] No such file or directory
/home/db_user/datacup-challenge-esi-dev/RequeteAPI/venv/bin/python: can't open file '/home/db_user/datacup-challenge-esi-dev/RequeteAPI/Importregulier.py': [Errno 2] No such file or directory
/home/db_user/datacup-challenge-esi-dev/RequeteAPI/venv/bin/python: can't open file '/home/db_user/datacup-challenge-esi-dev/RequeteAPI/Importregulier.py': [Errno 2] No such file or directory
/home/db_user/datacup-challenge-esi-dev/RequeteAPI/venv/bin/python: can't open file '/home/db_user/datacup-challenge-esi-dev/RequeteAPI/Importregulier.py': [Errno 2] No such file or directory
/home/db_user/datacup-challenge-esi-dev/RequeteAPI/venv/bin/python: can't open file '/home/db_user/datacup-challenge-esi-dev/RequeteAPI/Importregulier.py': [Errno 2] No such file or directory
/home/db_user/datacup-challenge-esi-dev/RequeteAPI/venv/bin/python: can't open file '/home/db_user/datacup-challenge-esi-dev/RequeteAPI/Importregulier.py': [Errno 2] No such file or directory
/home/db_user/datacup-challenge-esi-dev/RequeteAPI/venv/bin/python: can't open file '/home/db_user/datacup-challenge-esi-dev/RequeteAPI/Importregulier.py': [Errno 2] No such file or directory
/home/db_user/datacup-challenge-esi-dev/RequeteAPI/venv/bin/python: can't open file '/home/db_user/datacup-challenge-esi-dev/RequeteAPI/Importregulier.py': [Errno 2] No such file or directory
/home/db_user/datacup-challenge-esi-dev/RequeteAPI/venv/bin/python: can't open file '/home/db_user/datacup-challenge-esi-dev/RequeteAPI/Importregulier.py': [Errno 2] No such file or directory
/home/db_user/datacup-challenge-esi-dev/RequeteAPI/venv/bin/python: can't open file '/home/db_user/datacup-challenge-esi-dev/RequeteAPI/Importregulier.py': [Errno 2] No such file or directory
/home/db_user/datacup-challenge-esi-dev/RequeteAPI/venv/bin/python: can't open file '/home/db_user/datacup-challenge-esi-dev/RequeteAPI/Importregulier.py': [Errno 2] No such file or directory
/home/db_user/datacup-challenge-esi-dev/RequeteAPI/venv/bin/python: can't open file '/home/db_user/datacup-challenge-esi-dev/RequeteAPI/Importregulier.py': [Errno 2] No such file or directory
/home/db_user/datacup-challenge-esi-dev/RequeteAPI/venv/bin/python: can't open file '/home/db_user/datacup-challenge-esi-dev/RequeteAPI/Importregulier.py': [Errno 2] No such file or directory
/home/db_user/datacup-challenge-esi-dev/RequeteAPI/venv/bin/python: can't open file '/home/db_user/datacup-challenge-esi-dev/RequeteAPI/Importregulier.py': [Errno 2] No such file or directory
/home/db_user/datacup-challenge-esi-dev/RequeteAPI/venv/bin/python: can't open file '/home/db_user/datacup-challenge-esi-dev/RequeteAPI/Importregulier.py': [Errno 2] No such file or directory
/home/db_user/datacup-challenge-esi-dev/RequeteAPI/venv/bin/python: can't open file '/home/db_user/datacup-challenge-esi-dev/RequeteAPI/Importregulier.py': [Errno 2] No such file or directory
/home/db_user/datacup-challenge-esi-dev/RequeteAPI/venv/bin/python: can't open file '/home/db_user/datacup-challenge-esi-dev/RequeteAPI/Importregulier.py': [Errno 2] No such file or directory
/home/db_user/datacup-challenge-esi-dev/RequeteAPI/venv/bin/python: can't open file '/home/db_user/datacup-challenge-esi-dev/RequeteAPI/Importregulier.py': [Errno 2] No such file or directory
/home/db_user/datacup-challenge-esi-dev/RequeteAPI/venv/bin/python: can't open file '/home/db_user/datacup-challenge-esi-dev/RequeteAPI/Importregulier.py': [Errno 2] No such file or directory
/home/db_user/datacup-challenge-esi-dev/RequeteAPI/venv/bin/python: can't open file '/home/db_user/datacup-challenge-esi-dev/RequeteAPI/Importregulier.py': [Errno 2] No such file or directory
/home/db_user/datacup-challenge-esi-dev/RequeteAPI/venv/bin/python: can't open file '/home/db_user/datacup-challenge-esi-dev/RequeteAPI/Importregulier.py': [Errno 2] No such file or directory
/home/db_user/datacup-challenge-esi-dev/RequeteAPI/venv/bin/python: can't open file '/home/db_user/datacup-challenge-esi-dev/RequeteAPI/Importregulier.py': [Errno 2] No such file or directory
/home/db_user/datacup-challenge-esi-dev/RequeteAPI/venv/bin/python: can't open file '/home/db_user/datacup-challenge-esi-dev/RequeteAPI/Importregulier.py': [Errno 2] No such file or directory
/home/db_user/datacup-challenge-esi-dev/RequeteAPI/venv/bin/python: can't open file '/home/db_user/datacup-challenge-esi-dev/RequeteAPI/Importregulier.py': [Errno 2] No such file or directory
/home/db_user/datacup-challenge-esi-dev/RequeteAPI/venv/bin/python: can't open file '/home/db_user/datacup-challenge-esi-dev/RequeteAPI/Importregulier.py': [Errno 2] No such file or directory
/home/db_user/datacup-challenge-esi-dev/RequeteAPI/venv/bin/python: can't open file '/home/db_user/datacup-challenge-esi-dev/RequeteAPI/Importregulier.py': [Errno 2] No such file or directory
/home/db_user/datacup-challenge-esi-dev/RequeteAPI/venv/bin/python: can't open file '/home/db_user/datacup-challenge-esi-dev/RequeteAPI/Importregulier.py': [Errno 2] No such file or directory
/home/db_user/datacup-challenge-esi-dev/RequeteAPI/venv/bin/python: can't open file '/home/db_user/datacup-challenge-esi-dev/RequeteAPI/Importregulier.py': [Errno 2] No such file or directory
/home/db_user/datacup-challenge-esi-dev/RequeteAPI/venv/bin/python: can't open file '/home/db_user/datacup-challenge-esi-dev/RequeteAPI/Importregulier.py': [Errno 2] No such file or directory
/home/db_user/datacup-challenge-esi-dev/RequeteAPI/venv/bin/python: can't open file '/home/db_user/datacup-challenge-esi-dev/RequeteAPI/Importregulier.py': [Errno 2] No such file or directory
/home/db_user/datacup-challenge-esi-dev/RequeteAPI/venv/bin/python: can't open file '/home/db_user/datacup-challenge-esi-dev/RequeteAPI/Importregulier.py': [Errno 2] No such file or directory
/home/db_user/datacup-challenge-esi-dev/RequeteAPI/venv/bin/python: can't open file '/home/db_user/datacup-challenge-esi-dev/RequeteAPI/Importregulier.py': [Errno 2] No such file or directory
/home/db_user/datacup-challenge-esi-dev/RequeteAPI/venv/bin/python: can't open file '/home/db_user/datacup-challenge-esi-dev/RequeteAPI/Importregulier.py': [Errno 2] No such file or directory
/home/db_user/datacup-challenge-esi-dev/RequeteAPI/venv/bin/python: can't open file '/home/db_user/datacup-challenge-esi-dev/RequeteAPI/Importregulier.py': [Errno 2] No such file or directory
/home/db_user/datacup-challenge-esi-dev/RequeteAPI/venv/bin/python: can't open file '/home/db_user/datacup-challenge-esi-dev/RequeteAPI/Importregulier.py': [Errno 2] No such file or directory
/home/db_user/datacup-challenge-esi-dev/RequeteAPI/venv/bin/python: can't open file '/home/db_user/datacup-challenge-esi-dev/RequeteAPI/Importregulier.py': [Errno 2] No such file or directory
/home/db_user/datacup-challenge-esi-dev/RequeteAPI/venv/bin/python: can't open file '/home/db_user/datacup-challenge-esi-dev/RequeteAPI/Importregulier.py': [Errno 2] No such file or directory
/home/db_user/datacup-challenge-esi-dev/RequeteAPI/venv/bin/python: can't open file '/home/db_user/datacup-challenge-esi-dev/RequeteAPI/Importregulier.py': [Errno 2] No such file or directory
/home/db_user/datacup-challenge-esi-dev/RequeteAPI/venv/bin/python: can't open file '/home/db_user/datacup-challenge-esi-dev/RequeteAPI/Importregulier.py': [Errno 2] No such file or directory
/home/db_user/datacup-challenge-esi-dev/RequeteAPI/venv/bin/python: can't open file '/home/db_user/datacup-challenge-esi-dev/RequeteAPI/Importregulier.py': [Errno 2] No such file or directory
/home/db_user/datacup-challenge-esi-dev/RequeteAPI/venv/bin/python: can't open file '/home/db_user/datacup-challenge-esi-dev/RequeteAPI/Importregulier.py': [Errno 2] No such file or directory
/home/db_user/datacup-challenge-esi-dev/RequeteAPI/venv/bin/python: can't open file '/home/db_user/datacup-challenge-esi-dev/RequeteAPI/Importregulier.py': [Errno 2] No such file or directory
/home/db_user/datacup-challenge-esi-dev/RequeteAPI/venv/bin/python: can't open file '/home/db_user/datacup-challenge-esi-dev/RequeteAPI/Importregulier.py': [Errno 2] No such file or directory
/home/db_user/datacup-challenge-esi-dev/RequeteAPI/venv/bin/python: can't open file '/home/db_user/datacup-challenge-esi-dev/RequeteAPI/Importregulier.py': [Errno 2] No such file or directory
/home/db_user/datacup-challenge-esi-dev/RequeteAPI/venv/bin/python: can't open file '/home/db_user/datacup-challenge-esi-dev/RequeteAPI/Importregulier.py': [Errno 2] No such file or directory
/home/db_user/datacup-challenge-esi-dev/RequeteAPI/venv/bin/python: can't open file '/home/db_user/datacup-challenge-esi-dev/RequeteAPI/Importregulier.py': [Errno 2] No such file or directory
/home/db_user/datacup-challenge-esi-dev/RequeteAPI/venv/bin/python: can't open file '/home/db_user/datacup-challenge-esi-dev/RequeteAPI/Importregulier.py': [Errno 2] No such file or directory
/home/db_user/datacup-challenge-esi-dev/RequeteAPI/venv/bin/python: can't open file '/home/db_user/datacup-challenge-esi-dev/RequeteAPI/Importregulier.py': [Errno 2] No such file or directory
/home/db_user/datacup-challenge-esi-dev/RequeteAPI/venv/bin/python: can't open file '/home/db_user/datacup-challenge-esi-dev/RequeteAPI/Importregulier.py': [Errno 2] No such file or directory
/home/db_user/datacup-challenge-esi-dev/RequeteAPI/venv/bin/python: can't open file '/home/db_user/datacup-challenge-esi-dev/RequeteAPI/Importregulier.py': [Errno 2] No such file or directory
/home/db_user/datacup-challenge-esi-dev/RequeteAPI/venv/bin/python: can't open file '/home/db_user/datacup-challenge-esi-dev/RequeteAPI/Importregulier.py': [Errno 2] No such file or directory
/home/db_user/datacup-challenge-esi-dev/RequeteAPI/venv/bin/python: can't open file '/home/db_user/datacup-challenge-esi-dev/RequeteAPI/Importregulier.py': [Errno 2] No such file or directory
/home/db_user/datacup-challenge-esi-dev/RequeteAPI/venv/bin/python: can't open file '/home/db_user/datacup-challenge-esi-dev/RequeteAPI/Importregulier.py': [Errno 2] No such file or directory
/home/db_user/datacup-challenge-esi-dev/RequeteAPI/venv/bin/python: can't open file '/home/db_user/datacup-challenge-esi-dev/RequeteAPI/Importregulier.py': [Errno 2] No such file or directory
/home/db_user/datacup-challenge-esi-dev/RequeteAPI/venv/bin/python: can't open file '/home/db_user/datacup-challenge-esi-dev/RequeteAPI/Importregulier.py': [Errno 2] No such file or directory
/home/db_user/datacup-challenge-esi-dev/RequeteAPI/venv/bin/python: can't open file '/home/db_user/datacup-challenge-esi-dev/RequeteAPI/Importregulier.py': [Errno 2] No such file or directory
/home/db_user/datacup-challenge-esi-dev/RequeteAPI/venv/bin/python: can't open file '/home/db_user/datacup-challenge-esi-dev/RequeteAPI/Importregulier.py': [Errno 2] No such file or directory
/home/db_user/datacup-challenge-esi-dev/RequeteAPI/venv/bin/python: can't open file '/home/db_user/datacup-challenge-esi-dev/RequeteAPI/Importregulier.py': [Errno 2] No such file or directory
/home/db_user/datacup-challenge-esi-dev/RequeteAPI/venv/bin/python: can't open file '/home/db_user/datacup-challenge-esi-dev/RequeteAPI/Importregulier.py': [Errno 2] No such file or directory
/home/db_user/datacup-challenge-esi-dev/RequeteAPI/venv/bin/python: can't open file '/home/db_user/datacup-challenge-esi-dev/RequeteAPI/Importregulier.py': [Errno 2] No such file or directory
/home/db_user/datacup-challenge-esi-dev/RequeteAPI/venv/bin/python: can't open file '/home/db_user/datacup-challenge-esi-dev/RequeteAPI/Importregulier.py': [Errno 2] No such file or directory
/home/db_user/datacup-challenge-esi-dev/RequeteAPI/venv/bin/python: can't open file '/home/db_user/datacup-challenge-esi-dev/RequeteAPI/Importregulier.py': [Errno 2] No such file or directory
/home/db_user/datacup-challenge-esi-dev/RequeteAPI/venv/bin/python: can't open file '/home/db_user/datacup-challenge-esi-dev/RequeteAPI/Importregulier.py': [Errno 2] No such file or directory
/home/db_user/datacup-challenge-esi-dev/RequeteAPI/venv/bin/python: can't open file '/home/db_user/datacup-challenge-esi-dev/RequeteAPI/Importregulier.py': [Errno 2] No such file or directory
/home/db_user/datacup-challenge-esi-dev/RequeteAPI/venv/bin/python: can't open file '/home/db_user/datacup-challenge-esi-dev/RequeteAPI/Importregulier.py': [Errno 2] No such file or directory
/home/db_user/datacup-challenge-esi-dev/RequeteAPI/venv/bin/python: can't open file '/home/db_user/datacup-challenge-esi-dev/RequeteAPI/Importregulier.py': [Errno 2] No such file or directory
/home/db_user/datacup-challenge-esi-dev/RequeteAPI/venv/bin/python: can't open file '/home/db_user/datacup-challenge-esi-dev/RequeteAPI/Importregulier.py': [Errno 2] No such file or directory
/home/db_user/datacup-challenge-esi-dev/RequeteAPI/venv/bin/python: can't open file '/home/db_user/datacup-challenge-esi-dev/RequeteAPI/Importregulier.py': [Errno 2] No such file or directory
/home/db_user/datacup-challenge-esi-dev/RequeteAPI/venv/bin/python: can't open file '/home/db_user/datacup-challenge-esi-dev/RequeteAPI/Importregulier.py': [Errno 2] No such file or directory
/home/db_user/datacup-challenge-esi-dev/RequeteAPI/venv/bin/python: can't open file '/home/db_user/datacup-challenge-esi-dev/RequeteAPI/Importregulier.py': [Errno 2] No such file or directory
/home/db_user/datacup-challenge-esi-dev/RequeteAPI/venv/bin/python: can't open file '/home/db_user/datacup-challenge-esi-dev/RequeteAPI/Importregulier.py': [Errno 2] No such file or directory
/home/db_user/datacup-challenge-esi-dev/RequeteAPI/venv/bin/python: can't open file '/home/db_user/datacup-challenge-esi-dev/RequeteAPI/Importregulier.py': [Errno 2] No such file or directory
/home/db_user/datacup-challenge-esi-dev/RequeteAPI/venv/bin/python: can't open file '/home/db_user/datacup-challenge-esi-dev/RequeteAPI/Importregulier.py': [Errno 2] No such file or directory
/home/db_user/datacup-challenge-esi-dev/RequeteAPI/venv/bin/python: can't open file '/home/db_user/datacup-challenge-esi-dev/RequeteAPI/Importregulier.py': [Errno 2] No such file or directory
/home/db_user/datacup-challenge-esi-dev/RequeteAPI/venv/bin/python: can't open file '/home/db_user/datacup-challenge-esi-dev/RequeteAPI/Importregulier.py': [Errno 2] No such file or directory
/home/db_user/datacup-challenge-esi-dev/RequeteAPI/venv/bin/python: can't open file '/home/db_user/datacup-challenge-esi-dev/RequeteAPI/Importregulier.py': [Errno 2] No such file or directory
/home/db_user/datacup-challenge-esi-dev/RequeteAPI/venv/bin/python: can't open file '/home/db_user/datacup-challenge-esi-dev/RequeteAPI/Importregulier.py': [Errno 2] No such file or directory
/home/db_user/datacup-challenge-esi-dev/RequeteAPI/venv/bin/python: can't open file '/home/db_user/datacup-challenge-esi-dev/RequeteAPI/Importregulier.py': [Errno 2] No such file or directory
/home/db_user/datacup-challenge-esi-dev/RequeteAPI/venv/bin/python: can't open file '/home/db_user/datacup-challenge-esi-dev/RequeteAPI/Importregulier.py': [Errno 2] No such file or directory
/home/db_user/datacup-challenge-esi-dev/RequeteAPI/venv/bin/python: can't open file '/home/db_user/datacup-challenge-esi-dev/RequeteAPI/Importregulier.py': [Errno 2] No such file or directory
/home/db_user/datacup-challenge-esi-dev/RequeteAPI/venv/bin/python: can't open file '/home/db_user/datacup-challenge-esi-dev/RequeteAPI/Importregulier.py': [Errno 2] No such file or directory
/home/db_user/datacup-challenge-esi-dev/RequeteAPI/venv/bin/python: can't open file '/home/db_user/datacup-challenge-esi-dev/RequeteAPI/Importregulier.py': [Errno 2] No such file or directory
/home/db_user/datacup-challenge-esi-dev/RequeteAPI/venv/bin/python: can't open file '/home/db_user/datacup-challenge-esi-dev/RequeteAPI/Importregulier.py': [Errno 2] No such file or directory
/home/db_user/datacup-challenge-esi-dev/RequeteAPI/venv/bin/python: can't open file '/home/db_user/datacup-challenge-esi-dev/RequeteAPI/Importregulier.py': [Errno 2] No such file or directory
/home/db_user/datacup-challenge-esi-dev/RequeteAPI/venv/bin/python: can't open file '/home/db_user/datacup-challenge-esi-dev/RequeteAPI/Importregulier.py': [Errno 2] No such file or directory
/home/db_user/datacup-challenge-esi-dev/RequeteAPI/venv/bin/python: can't open file '/home/db_user/datacup-challenge-esi-dev/RequeteAPI/Importregulier.py': [Errno 2] No such file or directory
/home/db_user/datacup-challenge-esi-dev/RequeteAPI/venv/bin/python: can't open file '/home/db_user/datacup-challenge-esi-dev/RequeteAPI/Importregulier.py': [Errno 2] No such file or directory
/home/db_user/datacup-challenge-esi-dev/RequeteAPI/venv/bin/python: can't open file '/home/db_user/datacup-challenge-esi-dev/RequeteAPI/Importregulier.py': [Errno 2] No such file or directory
/home/db_user/datacup-challenge-esi-dev/RequeteAPI/venv/bin/python: can't open file '/home/db_user/datacup-challenge-esi-dev/RequeteAPI/Importregulier.py': [Errno 2] No such file or directory
/home/db_user/datacup-challenge-esi-dev/RequeteAPI/venv/bin/python: can't open file '/home/db_user/datacup-challenge-esi-dev/RequeteAPI/Importregulier.py': [Errno 2] No such file or directory
/home/db_user/datacup-challenge-esi-dev/RequeteAPI/venv/bin/python: can't open file '/home/db_user/datacup-challenge-esi-dev/RequeteAPI/Importregulier.py': [Errno 2] No such file or directory
/home/db_user/datacup-challenge-esi-dev/RequeteAPI/venv/bin/python: can't open file '/home/db_user/datacup-challenge-esi-dev/RequeteAPI/Importregulier.py': [Errno 2] No such file or directory
/home/db_user/datacup-challenge-esi-dev/RequeteAPI/venv/bin/python: can't open file '/home/db_user/datacup-challenge-esi-dev/RequeteAPI/Importregulier.py': [Errno 2] No such file or directory
/home/db_user/datacup-challenge-esi-dev/RequeteAPI/venv/bin/python: can't open file '/home/db_user/datacup-challenge-esi-dev/RequeteAPI/Importregulier.py': [Errno 2] No such file or directory
/home/db_user/datacup-challenge-esi-dev/RequeteAPI/venv/bin/python: can't open file '/home/db_user/datacup-challenge-esi-dev/RequeteAPI/Importregulier.py': [Errno 2] No such file or directory
/home/db_user/datacup-challenge-esi-dev/RequeteAPI/venv/bin/python: can't open file '/home/db_user/datacup-challenge-esi-dev/RequeteAPI/Importregulier.py': [Errno 2] No such file or directory
/home/db_user/datacup-challenge-esi-dev/RequeteAPI/venv/bin/python: can't open file '/home/db_user/datacup-challenge-esi-dev/RequeteAPI/Importregulier.py': [Errno 2] No such file or directory
/home/db_user/datacup-challenge-esi-dev/RequeteAPI/venv/bin/python: can't open file '/home/db_user/datacup-challenge-esi-dev/RequeteAPI/Importregulier.py': [Errno 2] No such file or directory
/home/db_user/datacup-challenge-esi-dev/RequeteAPI/venv/bin/python: can't open file '/home/db_user/datacup-challenge-esi-dev/RequeteAPI/Importregulier.py': [Errno 2] No such file or directory
/home/db_user/datacup-challenge-esi-dev/RequeteAPI/venv/bin/python: can't open file '/home/db_user/datacup-challenge-esi-dev/RequeteAPI/Importregulier.py': [Errno 2] No such file or directory
/home/db_user/datacup-challenge-esi-dev/RequeteAPI/venv/bin/python: can't open file '/home/db_user/datacup-challenge-esi-dev/RequeteAPI/Importregulier.py': [Errno 2] No such file or directory
/home/db_user/datacup-challenge-esi-dev/RequeteAPI/venv/bin/python: can't open file '/home/db_user/datacup-challenge-esi-dev/RequeteAPI/Importregulier.py': [Errno 2] No such file or directory
/home/db_user/datacup-challenge-esi-dev/RequeteAPI/venv/bin/python: can't open file '/home/db_user/datacup-challenge-esi-dev/RequeteAPI/Importregulier.py': [Errno 2] No such file or directory
/home/db_user/datacup-challenge-esi-dev/RequeteAPI/venv/bin/python: can't open file '/home/db_user/datacup-challenge-esi-dev/RequeteAPI/Importregulier.py': [Errno 2] No such file or directory
/home/db_user/datacup-challenge-esi-dev/RequeteAPI/venv/bin/python: can't open file '/home/db_user/datacup-challenge-esi-dev/RequeteAPI/Importregulier.py': [Errno 2] No such file or directory
/home/db_user/datacup-challenge-esi-dev/RequeteAPI/venv/bin/python: can't open file '/home/db_user/datacup-challenge-esi-dev/RequeteAPI/Importregulier.py': [Errno 2] No such file or directory
/home/db_user/datacup-challenge-esi-dev/RequeteAPI/venv/bin/python: can't open file '/home/db_user/datacup-challenge-esi-dev/RequeteAPI/Importregulier.py': [Errno 2] No such file or directory
/home/db_user/datacup-challenge-esi-dev/RequeteAPI/venv/bin/python: can't open file '/home/db_user/datacup-challenge-esi-dev/RequeteAPI/Importregulier.py': [Errno 2] No such file or directory
/home/db_user/datacup-challenge-esi-dev/RequeteAPI/venv/bin/python: can't open file '/home/db_user/datacup-challenge-esi-dev/RequeteAPI/Importregulier.py': [Errno 2] No such file or directory
/home/db_user/datacup-challenge-esi-dev/RequeteAPI/venv/bin/python: can't open file '/home/db_user/datacup-challenge-esi-dev/RequeteAPI/Importregulier.py': [Errno 2] No such file or directory
/home/db_user/datacup-challenge-esi-dev/RequeteAPI/venv/bin/python: can't open file '/home/db_user/datacup-challenge-esi-dev/RequeteAPI/Importregulier.py': [Errno 2] No such file or directory
/home/db_user/datacup-challenge-esi-dev/RequeteAPI/venv/bin/python: can't open file '/home/db_user/datacup-challenge-esi-dev/RequeteAPI/Importregulier.py': [Errno 2] No such file or directory
/home/db_user/datacup-challenge-esi-dev/RequeteAPI/venv/bin/python: can't open file '/home/db_user/datacup-challenge-esi-dev/RequeteAPI/Importregulier.py': [Errno 2] No such file or directory
/home/db_user/datacup-challenge-esi-dev/RequeteAPI/venv/bin/python: can't open file '/home/db_user/datacup-challenge-esi-dev/RequeteAPI/Importregulier.py': [Errno 2] No such file or directory
/home/db_user/datacup-challenge-esi-dev/RequeteAPI/venv/bin/python: can't open file '/home/db_user/datacup-challenge-esi-dev/RequeteAPI/Importregulier.py': [Errno 2] No such file or directory
/home/db_user/datacup-challenge-esi-dev/RequeteAPI/venv/bin/python: can't open file '/home/db_user/datacup-challenge-esi-dev/RequeteAPI/Importregulier.py': [Errno 2] No such file or directory
/home/db_user/datacup-challenge-esi-dev/RequeteAPI/venv/bin/python: can't open file '/home/db_user/datacup-challenge-esi-dev/RequeteAPI/Importregulier.py': [Errno 2] No such file or directory
/home/db_user/datacup-challenge-esi-dev/RequeteAPI/venv/bin/python: can't open file '/home/db_user/datacup-challenge-esi-dev/RequeteAPI/Importregulier.py': [Errno 2] No such file or directory
/home/db_user/datacup-challenge-esi-dev/RequeteAPI/venv/bin/python: can't open file '/home/db_user/datacup-challenge-esi-dev/RequeteAPI/Importregulier.py': [Errno 2] No such file or directory
/home/db_user/datacup-challenge-esi-dev/RequeteAPI/venv/bin/python: can't open file '/home/db_user/datacup-challenge-esi-dev/RequeteAPI/Importregulier.py': [Errno 2] No such file or directory
/home/db_user/datacup-challenge-esi-dev/RequeteAPI/venv/bin/python: can't open file '/home/db_user/datacup-challenge-esi-dev/RequeteAPI/Importregulier.py': [Errno 2] No such file or directory
/home/db_user/datacup-challenge-esi-dev/RequeteAPI/venv/bin/python: can't open file '/home/db_user/datacup-challenge-esi-dev/RequeteAPI/Importregulier.py': [Errno 2] No such file or directory
/home/db_user/datacup-challenge-esi-dev/RequeteAPI/venv/bin/python: can't open file '/home/db_user/datacup-challenge-esi-dev/RequeteAPI/Importregulier.py': [Errno 2] No such file or directory
/home/db_user/datacup-challenge-esi-dev/RequeteAPI/venv/bin/python: can't open file '/home/db_user/datacup-challenge-esi-dev/RequeteAPI/Importregulier.py': [Errno 2] No such file or directory
/home/db_user/datacup-challenge-esi-dev/RequeteAPI/venv/bin/python: can't open file '/home/db_user/datacup-challenge-esi-dev/RequeteAPI/Importregulier.py': [Errno 2] No such file or directory
/home/db_user/datacup-challenge-esi-dev/RequeteAPI/venv/bin/python: can't open file '/home/db_user/datacup-challenge-esi-dev/RequeteAPI/Importregulier.py': [Errno 2] No such file or directory
/home/db_user/datacup-challenge-esi-dev/RequeteAPI/venv/bin/python: can't open file '/home/db_user/datacup-challenge-esi-dev/RequeteAPI/Importregulier.py': [Errno 2] No such file or directory
/home/db_user/datacup-challenge-esi-dev/RequeteAPI/venv/bin/python: can't open file '/home/db_user/datacup-challenge-esi-dev/RequeteAPI/Importregulier.py': [Errno 2] No such file or directory
/home/db_user/datacup-challenge-esi-dev/RequeteAPI/venv/bin/python: can't open file '/home/db_user/datacup-challenge-esi-dev/RequeteAPI/Importregulier.py': [Errno 2] No such file or directory
/home/db_user/datacup-challenge-esi-dev/RequeteAPI/venv/bin/python: can't open file '/home/db_user/datacup-challenge-esi-dev/RequeteAPI/Importregulier.py': [Errno 2] No such file or directory
/home/db_user/datacup-challenge-esi-dev/RequeteAPI/venv/bin/python: can't open file '/home/db_user/datacup-challenge-esi-dev/RequeteAPI/Importregulier.py': [Errno 2] No such file or directory
/home/db_user/datacup-challenge-esi-dev/RequeteAPI/venv/bin/python: can't open file '/home/db_user/datacup-challenge-esi-dev/RequeteAPI/Importregulier.py': [Errno 2] No such file or directory
/home/db_user/datacup-challenge-esi-dev/RequeteAPI/venv/bin/python: can't open file '/home/db_user/datacup-challenge-esi-dev/RequeteAPI/Importregulier.py': [Errno 2] No such file or directory
/home/db_user/datacup-challenge-esi-dev/RequeteAPI/venv/bin/python: can't open file '/home/db_user/datacup-challenge-esi-dev/RequeteAPI/Importregulier.py': [Errno 2] No such file or directory
/home/db_user/datacup-challenge-esi-dev/RequeteAPI/venv/bin/python: can't open file '/home/db_user/datacup-challenge-esi-dev/RequeteAPI/Importregulier.py': [Errno 2] No such file or directory
/home/db_user/datacup-challenge-esi-dev/RequeteAPI/venv/bin/python: can't open file '/home/db_user/datacup-challenge-esi-dev/RequeteAPI/Importregulier.py': [Errno 2] No such file or directory
/home/db_user/datacup-challenge-esi-dev/RequeteAPI/venv/bin/python: can't open file '/home/db_user/datacup-challenge-esi-dev/RequeteAPI/Importregulier.py': [Errno 2] No such file or directory
/home/db_user/datacup-challenge-esi-dev/RequeteAPI/venv/bin/python: can't open file '/home/db_user/datacup-challenge-esi-dev/RequeteAPI/Importregulier.py': [Errno 2] No such file or directory
Date maximale : 2024-11-22 06:00:00
Aucune donnée supplémentaire trouvée.
Date maximale : 2024-11-22 06:00:00
Aucune donnée supplémentaire trouvée.
Date maximale : 2024-11-22 06:00:00
Aucune donnée supplémentaire trouvée.
Date maximale : 2024-11-22 06:00:00
Aucune donnée supplémentaire trouvée.
Date maximale : 2024-11-22 06:00:00
Aucune donnée supplémentaire trouvée.
Date maximale : 2024-11-22 06:00:00
Aucune donnée supplémentaire trouvée.
Date maximale : 2024-11-22 06:00:00
Aucune donnée supplémentaire trouvée.
Date maximale : 2024-11-22 06:00:00
Aucune donnée supplémentaire trouvée.
Date maximale : 2024-11-22 06:00:00
Aucune donnée supplémentaire trouvée.
Date maximale : 2024-11-22 06:00:00
Aucune donnée supplémentaire trouvée.
Date maximale : 2024-11-22 06:00:00
Aucune donnée supplémentaire trouvée.
Date maximale : 2024-11-22 06:00:00
Aucune donnée supplémentaire trouvée.
Date maximale : 2024-11-22 06:00:00
Aucune donnée supplémentaire trouvée.
Date maximale : 2024-11-22 06:00:00
Aucune donnée supplémentaire trouvée.
Date maximale : 2024-11-22 06:00:00
Aucune donnée supplémentaire trouvée.
Date maximale : 2024-11-22 06:00:00
Aucune donnée supplémentaire trouvée.
Date maximale : 2024-11-22 06:00:00
Aucune donnée supplémentaire trouvée.
Date maximale : 2024-11-22 06:00:00
Aucune donnée supplémentaire trouvée.
Date maximale : 2024-11-22 06:00:00
Aucune donnée supplémentaire trouvée.
Date maximale : 2024-11-22 06:00:00
Aucune donnée supplémentaire trouvée.
Date maximale : 2024-11-22 06:00:00
Aucune donnée supplémentaire trouvée.
Date maximale : 2024-11-22 06:00:00
Aucune donnée supplémentaire trouvée.
Date maximale : 2024-11-22 06:00:00
Aucune donnée supplémentaire trouvée.
Date maximale : 2024-11-22 06:00:00
Aucune donnée supplémentaire trouvée.
Date maximale : 2024-11-22 06:00:00
Aucune donnée supplémentaire trouvée.
Date maximale : 2024-11-22 06:00:00
Aucune donnée supplémentaire trouvée.
Date maximale : 2024-11-22 06:00:00
Aucune donnée supplémentaire trouvée.
Date maximale : 2024-11-22 06:00:00
Aucune donnée supplémentaire trouvée.
Date maximale : 2024-11-22 06:00:00
Aucune donnée supplémentaire trouvée.
Date maximale : 2024-11-22 06:00:00
Aucune donnée supplémentaire trouvée.
Date maximale : 2024-11-22 06:00:00
Aucune donnée supplémentaire trouvée.
Date maximale : 2024-11-22 06:00:00
Aucune donnée supplémentaire trouvée.
Date maximale : 2024-11-22 06:00:00
Aucune donnée supplémentaire trouvée.
Date maximale : 2024-11-22 06:00:00
Aucune donnée supplémentaire trouvée.
Date maximale : 2024-11-22 06:00:00
Aucune donnée supplémentaire trouvée.
Date maximale : 2024-11-22 06:00:00
Aucune donnée supplémentaire trouvée.
Date maximale : 2024-11-22 06:00:00
Traceback (most recent call last):
  File "/home/db_user/datacup-challenge-esi-dev/RequeteAPI/Importregulier.py", line 80, in <module>
    cursor.execute(insert_query, (station_id, pollutant, concentration, timestamp, typologie, nom_station, unite, object_id, x, y))
  File "/home/db_user/datacup-challenge-esi-dev/RequeteAPI/venv/lib/python3.12/site-packages/pymysql/cursors.py", line 153, in execute
    result = self._query(query)
             ^^^^^^^^^^^^^^^^^^
  File "/home/db_user/datacup-challenge-esi-dev/RequeteAPI/venv/lib/python3.12/site-packages/pymysql/cursors.py", line 322, in _query
    conn.query(q)
  File "/home/db_user/datacup-challenge-esi-dev/RequeteAPI/venv/lib/python3.12/site-packages/pymysql/connections.py", line 563, in query
    self._affected_rows = self._read_query_result(unbuffered=unbuffered)
                          ^^^^^^^^^^^^^^^^^^^^^^^^^^^^^^^^^^^^^^^^^^^^^^
  File "/home/db_user/datacup-challenge-esi-dev/RequeteAPI/venv/lib/python3.12/site-packages/pymysql/connections.py", line 825, in _read_query_result
    result.read()
  File "/home/db_user/datacup-challenge-esi-dev/RequeteAPI/venv/lib/python3.12/site-packages/pymysql/connections.py", line 1199, in read
    first_packet = self.connection._read_packet()
                   ^^^^^^^^^^^^^^^^^^^^^^^^^^^^^^
  File "/home/db_user/datacup-challenge-esi-dev/RequeteAPI/venv/lib/python3.12/site-packages/pymysql/connections.py", line 775, in _read_packet
    packet.raise_for_error()
  File "/home/db_user/datacup-challenge-esi-dev/RequeteAPI/venv/lib/python3.12/site-packages/pymysql/protocol.py", line 219, in raise_for_error
    err.raise_mysql_exception(self._data)
  File "/home/db_user/datacup-challenge-esi-dev/RequeteAPI/venv/lib/python3.12/site-packages/pymysql/err.py", line 150, in raise_mysql_exception
    raise errorclass(errno, errval)
pymysql.err.IntegrityError: (1062, "Duplicate entry '87071' for key 'PRIMARY'")
Date maximale : 2024-11-23 06:00:00
Aucune donnée supplémentaire trouvée.
Date maximale : 2024-11-23 06:00:00
Aucune donnée supplémentaire trouvée.
